WARNING:discord.client:PyNaCl is not installed, voice will NOT be supported
INFO:root:2024-05-24 19:30:32  Starting Bot...
INFO:discord.client:logging in using static token
INFO:discord.gateway:Shard ID None has connected to Gateway (Session ID: 878b7ef25b0ed29feb5a2a7d94a7c6ff).
INFO:__main__:Bot is Online and Ready!
INFO:root:<discord.ext.commands.context.Context object at 0x00000143C366E350>
INFO:root:304976615723499533
ERROR:root:Wrong Channel. minecraft was used instead.
ERROR:discord.ext.commands.bot:Ignoring exception in command start
Traceback (most recent call last):
  File "C:\Users\Administrator\AppData\Local\Programs\Python\Python311\Lib\site-packages\discord\ext\commands\core.py", line 235, in wrapped
    ret = await coro(*args, **kwargs)
          ^^^^^^^^^^^^^^^^^^^^^^^^^^^
  File "D:\Server Discord Bot\mcsbot.py", line 46, in start
    raise Exception("Incorrect Channel")
Exception: Incorrect Channel

The above exception was the direct cause of the following exception:

Traceback (most recent call last):
  File "C:\Users\Administrator\AppData\Local\Programs\Python\Python311\Lib\site-packages\discord\ext\commands\bot.py", line 1350, in invoke
    await ctx.command.invoke(ctx)
  File "C:\Users\Administrator\AppData\Local\Programs\Python\Python311\Lib\site-packages\discord\ext\commands\core.py", line 1029, in invoke
    await injected(*ctx.args, **ctx.kwargs)  # type: ignore
    ^^^^^^^^^^^^^^^^^^^^^^^^^^^^^^^^^^^^^^^
  File "C:\Users\Administrator\AppData\Local\Programs\Python\Python311\Lib\site-packages\discord\ext\commands\core.py", line 244, in wrapped
    raise CommandInvokeError(exc) from exc
discord.ext.commands.errors.CommandInvokeError: Command raised an exception: Exception: Incorrect Channel
ERROR:root:Wrong Channel. vanilla-server was used instead.
ERROR:discord.ext.commands.bot:Ignoring exception in command start
Traceback (most recent call last):
  File "C:\Users\Administrator\AppData\Local\Programs\Python\Python311\Lib\site-packages\discord\ext\commands\core.py", line 235, in wrapped
    ret = await coro(*args, **kwargs)
          ^^^^^^^^^^^^^^^^^^^^^^^^^^^
  File "D:\Server Discord Bot\mcsbot.py", line 45, in start
    await ctx.send(f"Please use the correct channel: minecraft")
  File "C:\Users\Administrator\AppData\Local\Programs\Python\Python311\Lib\site-packages\discord\ext\commands\context.py", line 1024, in send
    return await super().send(
           ^^^^^^^^^^^^^^^^^^^
  File "C:\Users\Administrator\AppData\Local\Programs\Python\Python311\Lib\site-packages\discord\abc.py", line 1561, in send
    data = await state.http.send_message(channel.id, params=params)
           ^^^^^^^^^^^^^^^^^^^^^^^^^^^^^^^^^^^^^^^^^^^^^^^^^^^^^^^^
  File "C:\Users\Administrator\AppData\Local\Programs\Python\Python311\Lib\site-packages\discord\http.py", line 739, in request
    raise Forbidden(response, data)
discord.errors.Forbidden: 403 Forbidden (error code: 50013): Missing Permissions

The above exception was the direct cause of the following exception:

Traceback (most recent call last):
  File "C:\Users\Administrator\AppData\Local\Programs\Python\Python311\Lib\site-packages\discord\ext\commands\bot.py", line 1350, in invoke
    await ctx.command.invoke(ctx)
  File "C:\Users\Administrator\AppData\Local\Programs\Python\Python311\Lib\site-packages\discord\ext\commands\core.py", line 1029, in invoke
    await injected(*ctx.args, **ctx.kwargs)  # type: ignore
    ^^^^^^^^^^^^^^^^^^^^^^^^^^^^^^^^^^^^^^^
  File "C:\Users\Administrator\AppData\Local\Programs\Python\Python311\Lib\site-packages\discord\ext\commands\core.py", line 244, in wrapped
    raise CommandInvokeError(exc) from exc
discord.ext.commands.errors.CommandInvokeError: Command raised an exception: Forbidden: 403 Forbidden (error code: 50013): Missing Permissions
ERROR:root:Wrong Channel. minecraft was used instead.
ERROR:discord.ext.commands.bot:Ignoring exception in command start
Traceback (most recent call last):
  File "C:\Users\Administrator\AppData\Local\Programs\Python\Python311\Lib\site-packages\discord\ext\commands\core.py", line 235, in wrapped
    ret = await coro(*args, **kwargs)
          ^^^^^^^^^^^^^^^^^^^^^^^^^^^
  File "D:\Server Discord Bot\mcsbot.py", line 46, in start
    raise Exception("Incorrect Channel")
Exception: Incorrect Channel

The above exception was the direct cause of the following exception:

Traceback (most recent call last):
  File "C:\Users\Administrator\AppData\Local\Programs\Python\Python311\Lib\site-packages\discord\ext\commands\bot.py", line 1350, in invoke
    await ctx.command.invoke(ctx)
  File "C:\Users\Administrator\AppData\Local\Programs\Python\Python311\Lib\site-packages\discord\ext\commands\core.py", line 1029, in invoke
    await injected(*ctx.args, **ctx.kwargs)  # type: ignore
    ^^^^^^^^^^^^^^^^^^^^^^^^^^^^^^^^^^^^^^^
  File "C:\Users\Administrator\AppData\Local\Programs\Python\Python311\Lib\site-packages\discord\ext\commands\core.py", line 244, in wrapped
    raise CommandInvokeError(exc) from exc
discord.ext.commands.errors.CommandInvokeError: Command raised an exception: Exception: Incorrect Channel
ERROR:root:Wrong Channel. vanilla-server was used instead.
ERROR:discord.ext.commands.bot:Ignoring exception in command start
Traceback (most recent call last):
  File "C:\Users\Administrator\AppData\Local\Programs\Python\Python311\Lib\site-packages\discord\ext\commands\core.py", line 235, in wrapped
    ret = await coro(*args, **kwargs)
          ^^^^^^^^^^^^^^^^^^^^^^^^^^^
  File "D:\Server Discord Bot\mcsbot.py", line 45, in start
    await ctx.send(f"Please use the correct channel: minecraft")
  File "C:\Users\Administrator\AppData\Local\Programs\Python\Python311\Lib\site-packages\discord\ext\commands\context.py", line 1024, in send
    return await super().send(
           ^^^^^^^^^^^^^^^^^^^
  File "C:\Users\Administrator\AppData\Local\Programs\Python\Python311\Lib\site-packages\discord\abc.py", line 1561, in send
    data = await state.http.send_message(channel.id, params=params)
           ^^^^^^^^^^^^^^^^^^^^^^^^^^^^^^^^^^^^^^^^^^^^^^^^^^^^^^^^
  File "C:\Users\Administrator\AppData\Local\Programs\Python\Python311\Lib\site-packages\discord\http.py", line 739, in request
    raise Forbidden(response, data)
discord.errors.Forbidden: 403 Forbidden (error code: 50013): Missing Permissions

The above exception was the direct cause of the following exception:

Traceback (most recent call last):
  File "C:\Users\Administrator\AppData\Local\Programs\Python\Python311\Lib\site-packages\discord\ext\commands\bot.py", line 1350, in invoke
    await ctx.command.invoke(ctx)
  File "C:\Users\Administrator\AppData\Local\Programs\Python\Python311\Lib\site-packages\discord\ext\commands\core.py", line 1029, in invoke
    await injected(*ctx.args, **ctx.kwargs)  # type: ignore
    ^^^^^^^^^^^^^^^^^^^^^^^^^^^^^^^^^^^^^^^
  File "C:\Users\Administrator\AppData\Local\Programs\Python\Python311\Lib\site-packages\discord\ext\commands\core.py", line 244, in wrapped
    raise CommandInvokeError(exc) from exc
discord.ext.commands.errors.CommandInvokeError: Command raised an exception: Forbidden: 403 Forbidden (error code: 50013): Missing Permissions
WARNING:discord.client:PyNaCl is not installed, voice will NOT be supported
INFO:root:2024-05-24 19:38:10  Starting Bot...
INFO:discord.client:logging in using static token
INFO:discord.gateway:Shard ID None has connected to Gateway (Session ID: 47d73572b2d331eb8726ba1c50c3e48f).
INFO:__main__:Bot is Online and Ready!
INFO:root:starting vanilla
INFO:root:Starting up browser
ERROR:root:BrowserType.launch: Executable doesn't exist at C:\Users\Administrator\AppData\Local\ms-playwright\webkit-2003\Playwright.exe
\u2554\u2550\u2550\u2550\u2550\u2550\u2550\u2550\u2550\u2550\u2550\u2550\u2550\u2550\u2550\u2550\u2550\u2550\u2550\u2550\u2550\u2550\u2550\u2550\u2550\u2550\u2550\u2550\u2550\u2550\u2550\u2550\u2550\u2550\u2550\u2550\u2550\u2550\u2550\u2550\u2550\u2550\u2550\u2550\u2550\u2550\u2550\u2550\u2550\u2550\u2550\u2550\u2550\u2550\u2550\u2550\u2550\u2550\u2550\u2550\u2550\u2557
\u2551 Looks like Playwright was just installed or updated.       \u2551
\u2551 Please run the following command to download new browsers: \u2551
\u2551                                                            \u2551
\u2551     playwright install                                     \u2551
\u2551                                                            \u2551
\u2551 <3 Playwright Team                                         \u2551
\u255a\u2550\u2550\u2550\u2550\u2550\u2550\u2550\u2550\u2550\u2550\u2550\u2550\u2550\u2550\u2550\u2550\u2550\u2550\u2550\u2550\u2550\u2550\u2550\u2550\u2550\u2550\u2550\u2550\u2550\u2550\u2550\u2550\u2550\u2550\u2550\u2550\u2550\u2550\u2550\u2550\u2550\u2550\u2550\u2550\u2550\u2550\u2550\u2550\u2550\u2550\u2550\u2550\u2550\u2550\u2550\u2550\u2550\u2550\u2550\u2550\u255d
INFO:root:starting vanilla
INFO:root:Starting up browser
ERROR:root:BrowserType.launch: Executable doesn't exist at C:\Users\Administrator\AppData\Local\ms-playwright\webkit-2003\Playwright.exe
\u2554\u2550\u2550\u2550\u2550\u2550\u2550\u2550\u2550\u2550\u2550\u2550\u2550\u2550\u2550\u2550\u2550\u2550\u2550\u2550\u2550\u2550\u2550\u2550\u2550\u2550\u2550\u2550\u2550\u2550\u2550\u2550\u2550\u2550\u2550\u2550\u2550\u2550\u2550\u2550\u2550\u2550\u2550\u2550\u2550\u2550\u2550\u2550\u2550\u2550\u2550\u2550\u2550\u2550\u2550\u2550\u2550\u2550\u2550\u2550\u2550\u2557
\u2551 Looks like Playwright was just installed or updated.       \u2551
\u2551 Please run the following command to download new browsers: \u2551
\u2551                                                            \u2551
\u2551     playwright install                                     \u2551
\u2551                                                            \u2551
\u2551 <3 Playwright Team                                         \u2551
\u255a\u2550\u2550\u2550\u2550\u2550\u2550\u2550\u2550\u2550\u2550\u2550\u2550\u2550\u2550\u2550\u2550\u2550\u2550\u2550\u2550\u2550\u2550\u2550\u2550\u2550\u2550\u2550\u2550\u2550\u2550\u2550\u2550\u2550\u2550\u2550\u2550\u2550\u2550\u2550\u2550\u2550\u2550\u2550\u2550\u2550\u2550\u2550\u2550\u2550\u2550\u2550\u2550\u2550\u2550\u2550\u2550\u2550\u2550\u2550\u2550\u255d
INFO:root:starting vanilla
INFO:root:Starting up browser
ERROR:root:BrowserType.launch: Executable doesn't exist at C:\Users\Administrator\AppData\Local\ms-playwright\webkit-2003\Playwright.exe
\u2554\u2550\u2550\u2550\u2550\u2550\u2550\u2550\u2550\u2550\u2550\u2550\u2550\u2550\u2550\u2550\u2550\u2550\u2550\u2550\u2550\u2550\u2550\u2550\u2550\u2550\u2550\u2550\u2550\u2550\u2550\u2550\u2550\u2550\u2550\u2550\u2550\u2550\u2550\u2550\u2550\u2550\u2550\u2550\u2550\u2550\u2550\u2550\u2550\u2550\u2550\u2550\u2550\u2550\u2550\u2550\u2550\u2550\u2550\u2550\u2550\u2557
\u2551 Looks like Playwright was just installed or updated.       \u2551
\u2551 Please run the following command to download new browsers: \u2551
\u2551                                                            \u2551
\u2551     playwright install                                     \u2551
\u2551                                                            \u2551
\u2551 <3 Playwright Team                                         \u2551
\u255a\u2550\u2550\u2550\u2550\u2550\u2550\u2550\u2550\u2550\u2550\u2550\u2550\u2550\u2550\u2550\u2550\u2550\u2550\u2550\u2550\u2550\u2550\u2550\u2550\u2550\u2550\u2550\u2550\u2550\u2550\u2550\u2550\u2550\u2550\u2550\u2550\u2550\u2550\u2550\u2550\u2550\u2550\u2550\u2550\u2550\u2550\u2550\u2550\u2550\u2550\u2550\u2550\u2550\u2550\u2550\u2550\u2550\u2550\u2550\u2550\u255d
INFO:root:starting vanilla
INFO:root:Starting up browser
INFO:root:Visiting MCS portal
INFO:root:Logging In
INFO:root:Starting Vanilla in MCS portal
INFO:root:Browser has been Closed
INFO:root:Vanilla has been started at 19:44
INFO:discord.gateway:Shard ID None has successfully RESUMED session 47d73572b2d331eb8726ba1c50c3e48f.
INFO:discord.gateway:Shard ID None has successfully RESUMED session 47d73572b2d331eb8726ba1c50c3e48f.
INFO:discord.gateway:Shard ID None has successfully RESUMED session 47d73572b2d331eb8726ba1c50c3e48f.
INFO:discord.gateway:Shard ID None has successfully RESUMED session 47d73572b2d331eb8726ba1c50c3e48f.
INFO:discord.gateway:Shard ID None has successfully RESUMED session 47d73572b2d331eb8726ba1c50c3e48f.
INFO:discord.gateway:Shard ID None has successfully RESUMED session 47d73572b2d331eb8726ba1c50c3e48f.
INFO:root:starting vanilla
INFO:root:Starting up browser
INFO:root:Visiting MCS portal
INFO:root:Logging In
INFO:root:Starting Vanilla in MCS portal
INFO:root:Browser has been Closed
INFO:root:Vanilla has been started at 09:34
INFO:discord.gateway:Shard ID None has successfully RESUMED session 47d73572b2d331eb8726ba1c50c3e48f.
INFO:discord.gateway:Shard ID None has successfully RESUMED session 47d73572b2d331eb8726ba1c50c3e48f.
INFO:discord.gateway:Shard ID None has successfully RESUMED session 47d73572b2d331eb8726ba1c50c3e48f.
INFO:discord.gateway:Shard ID None has successfully RESUMED session 47d73572b2d331eb8726ba1c50c3e48f.
INFO:discord.gateway:Shard ID None has successfully RESUMED session 47d73572b2d331eb8726ba1c50c3e48f.
INFO:discord.gateway:Shard ID None has successfully RESUMED session 47d73572b2d331eb8726ba1c50c3e48f.
INFO:discord.gateway:Shard ID None has successfully RESUMED session 47d73572b2d331eb8726ba1c50c3e48f.
INFO:discord.gateway:Shard ID None has successfully RESUMED session 47d73572b2d331eb8726ba1c50c3e48f.
INFO:discord.gateway:Shard ID None has successfully RESUMED session 47d73572b2d331eb8726ba1c50c3e48f.
INFO:discord.gateway:Shard ID None has successfully RESUMED session 47d73572b2d331eb8726ba1c50c3e48f.
INFO:discord.gateway:Shard ID None has successfully RESUMED session 47d73572b2d331eb8726ba1c50c3e48f.
INFO:discord.gateway:Shard ID None has successfully RESUMED session 47d73572b2d331eb8726ba1c50c3e48f.
INFO:discord.gateway:Shard ID None has successfully RESUMED session 47d73572b2d331eb8726ba1c50c3e48f.
INFO:discord.gateway:Shard ID None has successfully RESUMED session 47d73572b2d331eb8726ba1c50c3e48f.
INFO:discord.gateway:Shard ID None has successfully RESUMED session 47d73572b2d331eb8726ba1c50c3e48f.
INFO:discord.gateway:Shard ID None has successfully RESUMED session 47d73572b2d331eb8726ba1c50c3e48f.
ERROR:root:Wrong Channel. vanilla-server was used instead.
ERROR:discord.ext.commands.bot:Ignoring exception in command start
Traceback (most recent call last):
  File "C:\Users\Administrator\AppData\Local\Programs\Python\Python311\Lib\site-packages\discord\ext\commands\core.py", line 235, in wrapped
    ret = await coro(*args, **kwargs)
          ^^^^^^^^^^^^^^^^^^^^^^^^^^^
  File "D:\Server Discord Bot\mcsbot.py", line 45, in start
    await ctx.send(f"Please use the correct channel: minecraft")
  File "C:\Users\Administrator\AppData\Local\Programs\Python\Python311\Lib\site-packages\discord\ext\commands\context.py", line 1024, in send
    return await super().send(
           ^^^^^^^^^^^^^^^^^^^
  File "C:\Users\Administrator\AppData\Local\Programs\Python\Python311\Lib\site-packages\discord\abc.py", line 1561, in send
    data = await state.http.send_message(channel.id, params=params)
           ^^^^^^^^^^^^^^^^^^^^^^^^^^^^^^^^^^^^^^^^^^^^^^^^^^^^^^^^
  File "C:\Users\Administrator\AppData\Local\Programs\Python\Python311\Lib\site-packages\discord\http.py", line 739, in request
    raise Forbidden(response, data)
discord.errors.Forbidden: 403 Forbidden (error code: 50013): Missing Permissions

The above exception was the direct cause of the following exception:

Traceback (most recent call last):
  File "C:\Users\Administrator\AppData\Local\Programs\Python\Python311\Lib\site-packages\discord\ext\commands\bot.py", line 1350, in invoke
    await ctx.command.invoke(ctx)
  File "C:\Users\Administrator\AppData\Local\Programs\Python\Python311\Lib\site-packages\discord\ext\commands\core.py", line 1029, in invoke
    await injected(*ctx.args, **ctx.kwargs)  # type: ignore
    ^^^^^^^^^^^^^^^^^^^^^^^^^^^^^^^^^^^^^^^
  File "C:\Users\Administrator\AppData\Local\Programs\Python\Python311\Lib\site-packages\discord\ext\commands\core.py", line 244, in wrapped
    raise CommandInvokeError(exc) from exc
discord.ext.commands.errors.CommandInvokeError: Command raised an exception: Forbidden: 403 Forbidden (error code: 50013): Missing Permissions
ERROR:root:Wrong Channel. vanilla-server was used instead.
ERROR:discord.ext.commands.bot:Ignoring exception in command start
Traceback (most recent call last):
  File "C:\Users\Administrator\AppData\Local\Programs\Python\Python311\Lib\site-packages\discord\ext\commands\core.py", line 235, in wrapped
    ret = await coro(*args, **kwargs)
          ^^^^^^^^^^^^^^^^^^^^^^^^^^^
  File "D:\Server Discord Bot\mcsbot.py", line 45, in start
    await ctx.send(f"Please use the correct channel: minecraft")
  File "C:\Users\Administrator\AppData\Local\Programs\Python\Python311\Lib\site-packages\discord\ext\commands\context.py", line 1024, in send
    return await super().send(
           ^^^^^^^^^^^^^^^^^^^
  File "C:\Users\Administrator\AppData\Local\Programs\Python\Python311\Lib\site-packages\discord\abc.py", line 1561, in send
    data = await state.http.send_message(channel.id, params=params)
           ^^^^^^^^^^^^^^^^^^^^^^^^^^^^^^^^^^^^^^^^^^^^^^^^^^^^^^^^
  File "C:\Users\Administrator\AppData\Local\Programs\Python\Python311\Lib\site-packages\discord\http.py", line 739, in request
    raise Forbidden(response, data)
discord.errors.Forbidden: 403 Forbidden (error code: 50013): Missing Permissions

The above exception was the direct cause of the following exception:

Traceback (most recent call last):
  File "C:\Users\Administrator\AppData\Local\Programs\Python\Python311\Lib\site-packages\discord\ext\commands\bot.py", line 1350, in invoke
    await ctx.command.invoke(ctx)
  File "C:\Users\Administrator\AppData\Local\Programs\Python\Python311\Lib\site-packages\discord\ext\commands\core.py", line 1029, in invoke
    await injected(*ctx.args, **ctx.kwargs)  # type: ignore
    ^^^^^^^^^^^^^^^^^^^^^^^^^^^^^^^^^^^^^^^
  File "C:\Users\Administrator\AppData\Local\Programs\Python\Python311\Lib\site-packages\discord\ext\commands\core.py", line 244, in wrapped
    raise CommandInvokeError(exc) from exc
discord.ext.commands.errors.CommandInvokeError: Command raised an exception: Forbidden: 403 Forbidden (error code: 50013): Missing Permissions
ERROR:root:Wrong Channel. vanilla-server was used instead.
ERROR:discord.ext.commands.bot:Ignoring exception in command start
Traceback (most recent call last):
  File "C:\Users\Administrator\AppData\Local\Programs\Python\Python311\Lib\site-packages\discord\ext\commands\core.py", line 235, in wrapped
    ret = await coro(*args, **kwargs)
          ^^^^^^^^^^^^^^^^^^^^^^^^^^^
  File "D:\Server Discord Bot\mcsbot.py", line 45, in start
    await ctx.send(f"Please use the correct channel: minecraft")
  File "C:\Users\Administrator\AppData\Local\Programs\Python\Python311\Lib\site-packages\discord\ext\commands\context.py", line 1024, in send
    return await super().send(
           ^^^^^^^^^^^^^^^^^^^
  File "C:\Users\Administrator\AppData\Local\Programs\Python\Python311\Lib\site-packages\discord\abc.py", line 1561, in send
    data = await state.http.send_message(channel.id, params=params)
           ^^^^^^^^^^^^^^^^^^^^^^^^^^^^^^^^^^^^^^^^^^^^^^^^^^^^^^^^
  File "C:\Users\Administrator\AppData\Local\Programs\Python\Python311\Lib\site-packages\discord\http.py", line 739, in request
    raise Forbidden(response, data)
discord.errors.Forbidden: 403 Forbidden (error code: 50013): Missing Permissions

The above exception was the direct cause of the following exception:

Traceback (most recent call last):
  File "C:\Users\Administrator\AppData\Local\Programs\Python\Python311\Lib\site-packages\discord\ext\commands\bot.py", line 1350, in invoke
    await ctx.command.invoke(ctx)
  File "C:\Users\Administrator\AppData\Local\Programs\Python\Python311\Lib\site-packages\discord\ext\commands\core.py", line 1029, in invoke
    await injected(*ctx.args, **ctx.kwargs)  # type: ignore
    ^^^^^^^^^^^^^^^^^^^^^^^^^^^^^^^^^^^^^^^
  File "C:\Users\Administrator\AppData\Local\Programs\Python\Python311\Lib\site-packages\discord\ext\commands\core.py", line 244, in wrapped
    raise CommandInvokeError(exc) from exc
discord.ext.commands.errors.CommandInvokeError: Command raised an exception: Forbidden: 403 Forbidden (error code: 50013): Missing Permissions
INFO:discord.gateway:Shard ID None has successfully RESUMED session 47d73572b2d331eb8726ba1c50c3e48f.
INFO:discord.gateway:Shard ID None has successfully RESUMED session 47d73572b2d331eb8726ba1c50c3e48f.
ERROR:discord.client:Attempting a reconnect in 0.09s
Traceback (most recent call last):
  File "C:\Users\Administrator\AppData\Local\Programs\Python\Python311\Lib\site-packages\aiohttp\connector.py", line 1203, in _create_direct_connection
    hosts = await self._resolve_host(host, port, traces=traces)
            ^^^^^^^^^^^^^^^^^^^^^^^^^^^^^^^^^^^^^^^^^^^^^^^^^^^
  File "C:\Users\Administrator\AppData\Local\Programs\Python\Python311\Lib\site-packages\aiohttp\connector.py", line 880, in _resolve_host
    return await asyncio.shield(resolved_host_task)
           ^^^^^^^^^^^^^^^^^^^^^^^^^^^^^^^^^^^^^^^^
  File "C:\Users\Administrator\AppData\Local\Programs\Python\Python311\Lib\site-packages\aiohttp\connector.py", line 917, in _resolve_host_with_throttle
    addrs = await self._resolver.resolve(host, port, family=self._family)
            ^^^^^^^^^^^^^^^^^^^^^^^^^^^^^^^^^^^^^^^^^^^^^^^^^^^^^^^^^^^^^
  File "C:\Users\Administrator\AppData\Local\Programs\Python\Python311\Lib\site-packages\aiohttp\resolver.py", line 33, in resolve
    infos = await self._loop.getaddrinfo(
            ^^^^^^^^^^^^^^^^^^^^^^^^^^^^^
  File "C:\Users\Administrator\AppData\Local\Programs\Python\Python311\Lib\asyncio\base_events.py", line 867, in getaddrinfo
    return await self.run_in_executor(
           ^^^^^^^^^^^^^^^^^^^^^^^^^^^
  File "C:\Users\Administrator\AppData\Local\Programs\Python\Python311\Lib\concurrent\futures\thread.py", line 58, in run
    result = self.fn(*self.args, **self.kwargs)
             ^^^^^^^^^^^^^^^^^^^^^^^^^^^^^^^^^^
  File "C:\Users\Administrator\AppData\Local\Programs\Python\Python311\Lib\socket.py", line 962, in getaddrinfo
    for res in _socket.getaddrinfo(host, port, family, type, proto, flags):
               ^^^^^^^^^^^^^^^^^^^^^^^^^^^^^^^^^^^^^^^^^^^^^^^^^^^^^^^^^^^
socket.gaierror: [Errno 11001] getaddrinfo failed

The above exception was the direct cause of the following exception:

Traceback (most recent call last):
  File "C:\Users\Administrator\AppData\Local\Programs\Python\Python311\Lib\site-packages\discord\client.py", line 656, in connect
    self.ws = await asyncio.wait_for(coro, timeout=60.0)
              ^^^^^^^^^^^^^^^^^^^^^^^^^^^^^^^^^^^^^^^^^^
  File "C:\Users\Administrator\AppData\Local\Programs\Python\Python311\Lib\asyncio\tasks.py", line 479, in wait_for
    return fut.result()
           ^^^^^^^^^^^^
  File "C:\Users\Administrator\AppData\Local\Programs\Python\Python311\Lib\site-packages\discord\gateway.py", line 372, in from_client
    socket = await client.http.ws_connect(str(url))
             ^^^^^^^^^^^^^^^^^^^^^^^^^^^^^^^^^^^^^^
  File "C:\Users\Administrator\AppData\Local\Programs\Python\Python311\Lib\site-packages\discord\http.py", line 537, in ws_connect
    return await self.__session.ws_connect(url, **kwargs)
           ^^^^^^^^^^^^^^^^^^^^^^^^^^^^^^^^^^^^^^^^^^^^^^
  File "C:\Users\Administrator\AppData\Local\Programs\Python\Python311\Lib\site-packages\aiohttp\client.py", line 835, in _ws_connect
    resp = await self.request(
           ^^^^^^^^^^^^^^^^^^^
  File "C:\Users\Administrator\AppData\Local\Programs\Python\Python311\Lib\site-packages\aiohttp\client.py", line 581, in _request
    conn = await self._connector.connect(
           ^^^^^^^^^^^^^^^^^^^^^^^^^^^^^^
  File "C:\Users\Administrator\AppData\Local\Programs\Python\Python311\Lib\site-packages\aiohttp\connector.py", line 544, in connect
    proto = await self._create_connection(req, traces, timeout)
            ^^^^^^^^^^^^^^^^^^^^^^^^^^^^^^^^^^^^^^^^^^^^^^^^^^^
  File "C:\Users\Administrator\AppData\Local\Programs\Python\Python311\Lib\site-packages\aiohttp\connector.py", line 944, in _create_connection
    _, proto = await self._create_direct_connection(req, traces, timeout)
               ^^^^^^^^^^^^^^^^^^^^^^^^^^^^^^^^^^^^^^^^^^^^^^^^^^^^^^^^^^
  File "C:\Users\Administrator\AppData\Local\Programs\Python\Python311\Lib\site-packages\aiohttp\connector.py", line 1209, in _create_direct_connection
    raise ClientConnectorError(req.connection_key, exc) from exc
aiohttp.client_exceptions.ClientConnectorError: Cannot connect to host gateway-us-east1-d.discord.gg:443 ssl:default [getaddrinfo failed]
ERROR:discord.client:Attempting a reconnect in 2.60s
Traceback (most recent call last):
  File "C:\Users\Administrator\AppData\Local\Programs\Python\Python311\Lib\site-packages\aiohttp\connector.py", line 1203, in _create_direct_connection
    hosts = await self._resolve_host(host, port, traces=traces)
            ^^^^^^^^^^^^^^^^^^^^^^^^^^^^^^^^^^^^^^^^^^^^^^^^^^^
  File "C:\Users\Administrator\AppData\Local\Programs\Python\Python311\Lib\site-packages\aiohttp\connector.py", line 880, in _resolve_host
    return await asyncio.shield(resolved_host_task)
           ^^^^^^^^^^^^^^^^^^^^^^^^^^^^^^^^^^^^^^^^
  File "C:\Users\Administrator\AppData\Local\Programs\Python\Python311\Lib\site-packages\aiohttp\connector.py", line 917, in _resolve_host_with_throttle
    addrs = await self._resolver.resolve(host, port, family=self._family)
            ^^^^^^^^^^^^^^^^^^^^^^^^^^^^^^^^^^^^^^^^^^^^^^^^^^^^^^^^^^^^^
  File "C:\Users\Administrator\AppData\Local\Programs\Python\Python311\Lib\site-packages\aiohttp\resolver.py", line 33, in resolve
    infos = await self._loop.getaddrinfo(
            ^^^^^^^^^^^^^^^^^^^^^^^^^^^^^
  File "C:\Users\Administrator\AppData\Local\Programs\Python\Python311\Lib\asyncio\base_events.py", line 867, in getaddrinfo
    return await self.run_in_executor(
           ^^^^^^^^^^^^^^^^^^^^^^^^^^^
  File "C:\Users\Administrator\AppData\Local\Programs\Python\Python311\Lib\concurrent\futures\thread.py", line 58, in run
    result = self.fn(*self.args, **self.kwargs)
             ^^^^^^^^^^^^^^^^^^^^^^^^^^^^^^^^^^
  File "C:\Users\Administrator\AppData\Local\Programs\Python\Python311\Lib\socket.py", line 962, in getaddrinfo
    for res in _socket.getaddrinfo(host, port, family, type, proto, flags):
               ^^^^^^^^^^^^^^^^^^^^^^^^^^^^^^^^^^^^^^^^^^^^^^^^^^^^^^^^^^^
socket.gaierror: [Errno 11001] getaddrinfo failed

The above exception was the direct cause of the following exception:

Traceback (most recent call last):
  File "C:\Users\Administrator\AppData\Local\Programs\Python\Python311\Lib\site-packages\discord\client.py", line 656, in connect
    self.ws = await asyncio.wait_for(coro, timeout=60.0)
              ^^^^^^^^^^^^^^^^^^^^^^^^^^^^^^^^^^^^^^^^^^
  File "C:\Users\Administrator\AppData\Local\Programs\Python\Python311\Lib\asyncio\tasks.py", line 479, in wait_for
    return fut.result()
           ^^^^^^^^^^^^
  File "C:\Users\Administrator\AppData\Local\Programs\Python\Python311\Lib\site-packages\discord\gateway.py", line 372, in from_client
    socket = await client.http.ws_connect(str(url))
             ^^^^^^^^^^^^^^^^^^^^^^^^^^^^^^^^^^^^^^
  File "C:\Users\Administrator\AppData\Local\Programs\Python\Python311\Lib\site-packages\discord\http.py", line 537, in ws_connect
    return await self.__session.ws_connect(url, **kwargs)
           ^^^^^^^^^^^^^^^^^^^^^^^^^^^^^^^^^^^^^^^^^^^^^^
  File "C:\Users\Administrator\AppData\Local\Programs\Python\Python311\Lib\site-packages\aiohttp\client.py", line 835, in _ws_connect
    resp = await self.request(
           ^^^^^^^^^^^^^^^^^^^
  File "C:\Users\Administrator\AppData\Local\Programs\Python\Python311\Lib\site-packages\aiohttp\client.py", line 581, in _request
    conn = await self._connector.connect(
           ^^^^^^^^^^^^^^^^^^^^^^^^^^^^^^
  File "C:\Users\Administrator\AppData\Local\Programs\Python\Python311\Lib\site-packages\aiohttp\connector.py", line 544, in connect
    proto = await self._create_connection(req, traces, timeout)
            ^^^^^^^^^^^^^^^^^^^^^^^^^^^^^^^^^^^^^^^^^^^^^^^^^^^
  File "C:\Users\Administrator\AppData\Local\Programs\Python\Python311\Lib\site-packages\aiohttp\connector.py", line 944, in _create_connection
    _, proto = await self._create_direct_connection(req, traces, timeout)
               ^^^^^^^^^^^^^^^^^^^^^^^^^^^^^^^^^^^^^^^^^^^^^^^^^^^^^^^^^^
  File "C:\Users\Administrator\AppData\Local\Programs\Python\Python311\Lib\site-packages\aiohttp\connector.py", line 1209, in _create_direct_connection
    raise ClientConnectorError(req.connection_key, exc) from exc
aiohttp.client_exceptions.ClientConnectorError: Cannot connect to host gateway-us-east1-d.discord.gg:443 ssl:default [getaddrinfo failed]
ERROR:discord.client:Attempting a reconnect in 1.67s
Traceback (most recent call last):
  File "C:\Users\Administrator\AppData\Local\Programs\Python\Python311\Lib\site-packages\aiohttp\connector.py", line 1203, in _create_direct_connection
    hosts = await self._resolve_host(host, port, traces=traces)
            ^^^^^^^^^^^^^^^^^^^^^^^^^^^^^^^^^^^^^^^^^^^^^^^^^^^
  File "C:\Users\Administrator\AppData\Local\Programs\Python\Python311\Lib\site-packages\aiohttp\connector.py", line 880, in _resolve_host
    return await asyncio.shield(resolved_host_task)
           ^^^^^^^^^^^^^^^^^^^^^^^^^^^^^^^^^^^^^^^^
  File "C:\Users\Administrator\AppData\Local\Programs\Python\Python311\Lib\site-packages\aiohttp\connector.py", line 917, in _resolve_host_with_throttle
    addrs = await self._resolver.resolve(host, port, family=self._family)
            ^^^^^^^^^^^^^^^^^^^^^^^^^^^^^^^^^^^^^^^^^^^^^^^^^^^^^^^^^^^^^
  File "C:\Users\Administrator\AppData\Local\Programs\Python\Python311\Lib\site-packages\aiohttp\resolver.py", line 33, in resolve
    infos = await self._loop.getaddrinfo(
            ^^^^^^^^^^^^^^^^^^^^^^^^^^^^^
  File "C:\Users\Administrator\AppData\Local\Programs\Python\Python311\Lib\asyncio\base_events.py", line 867, in getaddrinfo
    return await self.run_in_executor(
           ^^^^^^^^^^^^^^^^^^^^^^^^^^^
  File "C:\Users\Administrator\AppData\Local\Programs\Python\Python311\Lib\concurrent\futures\thread.py", line 58, in run
    result = self.fn(*self.args, **self.kwargs)
             ^^^^^^^^^^^^^^^^^^^^^^^^^^^^^^^^^^
  File "C:\Users\Administrator\AppData\Local\Programs\Python\Python311\Lib\socket.py", line 962, in getaddrinfo
    for res in _socket.getaddrinfo(host, port, family, type, proto, flags):
               ^^^^^^^^^^^^^^^^^^^^^^^^^^^^^^^^^^^^^^^^^^^^^^^^^^^^^^^^^^^
socket.gaierror: [Errno 11001] getaddrinfo failed

The above exception was the direct cause of the following exception:

Traceback (most recent call last):
  File "C:\Users\Administrator\AppData\Local\Programs\Python\Python311\Lib\site-packages\discord\client.py", line 656, in connect
    self.ws = await asyncio.wait_for(coro, timeout=60.0)
              ^^^^^^^^^^^^^^^^^^^^^^^^^^^^^^^^^^^^^^^^^^
  File "C:\Users\Administrator\AppData\Local\Programs\Python\Python311\Lib\asyncio\tasks.py", line 479, in wait_for
    return fut.result()
           ^^^^^^^^^^^^
  File "C:\Users\Administrator\AppData\Local\Programs\Python\Python311\Lib\site-packages\discord\gateway.py", line 372, in from_client
    socket = await client.http.ws_connect(str(url))
             ^^^^^^^^^^^^^^^^^^^^^^^^^^^^^^^^^^^^^^
  File "C:\Users\Administrator\AppData\Local\Programs\Python\Python311\Lib\site-packages\discord\http.py", line 537, in ws_connect
    return await self.__session.ws_connect(url, **kwargs)
           ^^^^^^^^^^^^^^^^^^^^^^^^^^^^^^^^^^^^^^^^^^^^^^
  File "C:\Users\Administrator\AppData\Local\Programs\Python\Python311\Lib\site-packages\aiohttp\client.py", line 835, in _ws_connect
    resp = await self.request(
           ^^^^^^^^^^^^^^^^^^^
  File "C:\Users\Administrator\AppData\Local\Programs\Python\Python311\Lib\site-packages\aiohttp\client.py", line 581, in _request
    conn = await self._connector.connect(
           ^^^^^^^^^^^^^^^^^^^^^^^^^^^^^^
  File "C:\Users\Administrator\AppData\Local\Programs\Python\Python311\Lib\site-packages\aiohttp\connector.py", line 544, in connect
    proto = await self._create_connection(req, traces, timeout)
            ^^^^^^^^^^^^^^^^^^^^^^^^^^^^^^^^^^^^^^^^^^^^^^^^^^^
  File "C:\Users\Administrator\AppData\Local\Programs\Python\Python311\Lib\site-packages\aiohttp\connector.py", line 944, in _create_connection
    _, proto = await self._create_direct_connection(req, traces, timeout)
               ^^^^^^^^^^^^^^^^^^^^^^^^^^^^^^^^^^^^^^^^^^^^^^^^^^^^^^^^^^
  File "C:\Users\Administrator\AppData\Local\Programs\Python\Python311\Lib\site-packages\aiohttp\connector.py", line 1209, in _create_direct_connection
    raise ClientConnectorError(req.connection_key, exc) from exc
aiohttp.client_exceptions.ClientConnectorError: Cannot connect to host gateway-us-east1-d.discord.gg:443 ssl:default [getaddrinfo failed]
ERROR:discord.client:Attempting a reconnect in 2.98s
Traceback (most recent call last):
  File "C:\Users\Administrator\AppData\Local\Programs\Python\Python311\Lib\site-packages\aiohttp\connector.py", line 1203, in _create_direct_connection
    hosts = await self._resolve_host(host, port, traces=traces)
            ^^^^^^^^^^^^^^^^^^^^^^^^^^^^^^^^^^^^^^^^^^^^^^^^^^^
  File "C:\Users\Administrator\AppData\Local\Programs\Python\Python311\Lib\site-packages\aiohttp\connector.py", line 880, in _resolve_host
    return await asyncio.shield(resolved_host_task)
           ^^^^^^^^^^^^^^^^^^^^^^^^^^^^^^^^^^^^^^^^
  File "C:\Users\Administrator\AppData\Local\Programs\Python\Python311\Lib\site-packages\aiohttp\connector.py", line 917, in _resolve_host_with_throttle
    addrs = await self._resolver.resolve(host, port, family=self._family)
            ^^^^^^^^^^^^^^^^^^^^^^^^^^^^^^^^^^^^^^^^^^^^^^^^^^^^^^^^^^^^^
  File "C:\Users\Administrator\AppData\Local\Programs\Python\Python311\Lib\site-packages\aiohttp\resolver.py", line 33, in resolve
    infos = await self._loop.getaddrinfo(
            ^^^^^^^^^^^^^^^^^^^^^^^^^^^^^
  File "C:\Users\Administrator\AppData\Local\Programs\Python\Python311\Lib\asyncio\base_events.py", line 867, in getaddrinfo
    return await self.run_in_executor(
           ^^^^^^^^^^^^^^^^^^^^^^^^^^^
  File "C:\Users\Administrator\AppData\Local\Programs\Python\Python311\Lib\concurrent\futures\thread.py", line 58, in run
    result = self.fn(*self.args, **self.kwargs)
             ^^^^^^^^^^^^^^^^^^^^^^^^^^^^^^^^^^
  File "C:\Users\Administrator\AppData\Local\Programs\Python\Python311\Lib\socket.py", line 962, in getaddrinfo
    for res in _socket.getaddrinfo(host, port, family, type, proto, flags):
               ^^^^^^^^^^^^^^^^^^^^^^^^^^^^^^^^^^^^^^^^^^^^^^^^^^^^^^^^^^^
socket.gaierror: [Errno 11001] getaddrinfo failed

The above exception was the direct cause of the following exception:

Traceback (most recent call last):
  File "C:\Users\Administrator\AppData\Local\Programs\Python\Python311\Lib\site-packages\discord\client.py", line 656, in connect
    self.ws = await asyncio.wait_for(coro, timeout=60.0)
              ^^^^^^^^^^^^^^^^^^^^^^^^^^^^^^^^^^^^^^^^^^
  File "C:\Users\Administrator\AppData\Local\Programs\Python\Python311\Lib\asyncio\tasks.py", line 479, in wait_for
    return fut.result()
           ^^^^^^^^^^^^
  File "C:\Users\Administrator\AppData\Local\Programs\Python\Python311\Lib\site-packages\discord\gateway.py", line 372, in from_client
    socket = await client.http.ws_connect(str(url))
             ^^^^^^^^^^^^^^^^^^^^^^^^^^^^^^^^^^^^^^
  File "C:\Users\Administrator\AppData\Local\Programs\Python\Python311\Lib\site-packages\discord\http.py", line 537, in ws_connect
    return await self.__session.ws_connect(url, **kwargs)
           ^^^^^^^^^^^^^^^^^^^^^^^^^^^^^^^^^^^^^^^^^^^^^^
  File "C:\Users\Administrator\AppData\Local\Programs\Python\Python311\Lib\site-packages\aiohttp\client.py", line 835, in _ws_connect
    resp = await self.request(
           ^^^^^^^^^^^^^^^^^^^
  File "C:\Users\Administrator\AppData\Local\Programs\Python\Python311\Lib\site-packages\aiohttp\client.py", line 581, in _request
    conn = await self._connector.connect(
           ^^^^^^^^^^^^^^^^^^^^^^^^^^^^^^
  File "C:\Users\Administrator\AppData\Local\Programs\Python\Python311\Lib\site-packages\aiohttp\connector.py", line 544, in connect
    proto = await self._create_connection(req, traces, timeout)
            ^^^^^^^^^^^^^^^^^^^^^^^^^^^^^^^^^^^^^^^^^^^^^^^^^^^
  File "C:\Users\Administrator\AppData\Local\Programs\Python\Python311\Lib\site-packages\aiohttp\connector.py", line 944, in _create_connection
    _, proto = await self._create_direct_connection(req, traces, timeout)
               ^^^^^^^^^^^^^^^^^^^^^^^^^^^^^^^^^^^^^^^^^^^^^^^^^^^^^^^^^^
  File "C:\Users\Administrator\AppData\Local\Programs\Python\Python311\Lib\site-packages\aiohttp\connector.py", line 1209, in _create_direct_connection
    raise ClientConnectorError(req.connection_key, exc) from exc
aiohttp.client_exceptions.ClientConnectorError: Cannot connect to host gateway-us-east1-d.discord.gg:443 ssl:default [getaddrinfo failed]
ERROR:discord.client:Attempting a reconnect in 30.56s
Traceback (most recent call last):
  File "C:\Users\Administrator\AppData\Local\Programs\Python\Python311\Lib\site-packages\aiohttp\connector.py", line 1203, in _create_direct_connection
    hosts = await self._resolve_host(host, port, traces=traces)
            ^^^^^^^^^^^^^^^^^^^^^^^^^^^^^^^^^^^^^^^^^^^^^^^^^^^
  File "C:\Users\Administrator\AppData\Local\Programs\Python\Python311\Lib\site-packages\aiohttp\connector.py", line 880, in _resolve_host
    return await asyncio.shield(resolved_host_task)
           ^^^^^^^^^^^^^^^^^^^^^^^^^^^^^^^^^^^^^^^^
  File "C:\Users\Administrator\AppData\Local\Programs\Python\Python311\Lib\site-packages\aiohttp\connector.py", line 917, in _resolve_host_with_throttle
    addrs = await self._resolver.resolve(host, port, family=self._family)
            ^^^^^^^^^^^^^^^^^^^^^^^^^^^^^^^^^^^^^^^^^^^^^^^^^^^^^^^^^^^^^
  File "C:\Users\Administrator\AppData\Local\Programs\Python\Python311\Lib\site-packages\aiohttp\resolver.py", line 33, in resolve
    infos = await self._loop.getaddrinfo(
            ^^^^^^^^^^^^^^^^^^^^^^^^^^^^^
  File "C:\Users\Administrator\AppData\Local\Programs\Python\Python311\Lib\asyncio\base_events.py", line 867, in getaddrinfo
    return await self.run_in_executor(
           ^^^^^^^^^^^^^^^^^^^^^^^^^^^
  File "C:\Users\Administrator\AppData\Local\Programs\Python\Python311\Lib\concurrent\futures\thread.py", line 58, in run
    result = self.fn(*self.args, **self.kwargs)
             ^^^^^^^^^^^^^^^^^^^^^^^^^^^^^^^^^^
  File "C:\Users\Administrator\AppData\Local\Programs\Python\Python311\Lib\socket.py", line 962, in getaddrinfo
    for res in _socket.getaddrinfo(host, port, family, type, proto, flags):
               ^^^^^^^^^^^^^^^^^^^^^^^^^^^^^^^^^^^^^^^^^^^^^^^^^^^^^^^^^^^
socket.gaierror: [Errno 11001] getaddrinfo failed

The above exception was the direct cause of the following exception:

Traceback (most recent call last):
  File "C:\Users\Administrator\AppData\Local\Programs\Python\Python311\Lib\site-packages\discord\client.py", line 656, in connect
    self.ws = await asyncio.wait_for(coro, timeout=60.0)
              ^^^^^^^^^^^^^^^^^^^^^^^^^^^^^^^^^^^^^^^^^^
  File "C:\Users\Administrator\AppData\Local\Programs\Python\Python311\Lib\asyncio\tasks.py", line 479, in wait_for
    return fut.result()
           ^^^^^^^^^^^^
  File "C:\Users\Administrator\AppData\Local\Programs\Python\Python311\Lib\site-packages\discord\gateway.py", line 372, in from_client
    socket = await client.http.ws_connect(str(url))
             ^^^^^^^^^^^^^^^^^^^^^^^^^^^^^^^^^^^^^^
  File "C:\Users\Administrator\AppData\Local\Programs\Python\Python311\Lib\site-packages\discord\http.py", line 537, in ws_connect
    return await self.__session.ws_connect(url, **kwargs)
           ^^^^^^^^^^^^^^^^^^^^^^^^^^^^^^^^^^^^^^^^^^^^^^
  File "C:\Users\Administrator\AppData\Local\Programs\Python\Python311\Lib\site-packages\aiohttp\client.py", line 835, in _ws_connect
    resp = await self.request(
           ^^^^^^^^^^^^^^^^^^^
  File "C:\Users\Administrator\AppData\Local\Programs\Python\Python311\Lib\site-packages\aiohttp\client.py", line 581, in _request
    conn = await self._connector.connect(
           ^^^^^^^^^^^^^^^^^^^^^^^^^^^^^^
  File "C:\Users\Administrator\AppData\Local\Programs\Python\Python311\Lib\site-packages\aiohttp\connector.py", line 544, in connect
    proto = await self._create_connection(req, traces, timeout)
            ^^^^^^^^^^^^^^^^^^^^^^^^^^^^^^^^^^^^^^^^^^^^^^^^^^^
  File "C:\Users\Administrator\AppData\Local\Programs\Python\Python311\Lib\site-packages\aiohttp\connector.py", line 944, in _create_connection
    _, proto = await self._create_direct_connection(req, traces, timeout)
               ^^^^^^^^^^^^^^^^^^^^^^^^^^^^^^^^^^^^^^^^^^^^^^^^^^^^^^^^^^
  File "C:\Users\Administrator\AppData\Local\Programs\Python\Python311\Lib\site-packages\aiohttp\connector.py", line 1209, in _create_direct_connection
    raise ClientConnectorError(req.connection_key, exc) from exc
aiohttp.client_exceptions.ClientConnectorError: Cannot connect to host gateway-us-east1-d.discord.gg:443 ssl:default [getaddrinfo failed]
INFO:discord.gateway:Shard ID None session has been invalidated.
INFO:discord.gateway:Shard ID None has connected to Gateway (Session ID: c69b02593bf94ed9f5653ae33812764b).
INFO:__main__:Bot is Online and Ready!
INFO:discord.gateway:Shard ID None has successfully RESUMED session c69b02593bf94ed9f5653ae33812764b.
INFO:discord.gateway:Shard ID None has successfully RESUMED session c69b02593bf94ed9f5653ae33812764b.
INFO:discord.gateway:Shard ID None has successfully RESUMED session c69b02593bf94ed9f5653ae33812764b.
INFO:discord.gateway:Shard ID None has successfully RESUMED session c69b02593bf94ed9f5653ae33812764b.
INFO:root:starting vanilla
INFO:root:Starting up browser
INFO:root:Visiting MCS portal
INFO:root:Logging In
INFO:root:Starting Vanilla in MCS portal
INFO:root:Browser has been Closed
INFO:root:Vanilla has been started at 13:57
ERROR:root:Wrong Channel. vanilla-server was used instead.
ERROR:discord.ext.commands.bot:Ignoring exception in command start
Traceback (most recent call last):
  File "C:\Users\Administrator\AppData\Local\Programs\Python\Python311\Lib\site-packages\discord\ext\commands\core.py", line 235, in wrapped
    ret = await coro(*args, **kwargs)
          ^^^^^^^^^^^^^^^^^^^^^^^^^^^
  File "D:\Server Discord Bot\mcsbot.py", line 46, in start
    raise Exception("Incorrect Channel")
Exception: Incorrect Channel

The above exception was the direct cause of the following exception:

Traceback (most recent call last):
  File "C:\Users\Administrator\AppData\Local\Programs\Python\Python311\Lib\site-packages\discord\ext\commands\bot.py", line 1350, in invoke
    await ctx.command.invoke(ctx)
  File "C:\Users\Administrator\AppData\Local\Programs\Python\Python311\Lib\site-packages\discord\ext\commands\core.py", line 1029, in invoke
    await injected(*ctx.args, **ctx.kwargs)  # type: ignore
    ^^^^^^^^^^^^^^^^^^^^^^^^^^^^^^^^^^^^^^^
  File "C:\Users\Administrator\AppData\Local\Programs\Python\Python311\Lib\site-packages\discord\ext\commands\core.py", line 244, in wrapped
    raise CommandInvokeError(exc) from exc
discord.ext.commands.errors.CommandInvokeError: Command raised an exception: Exception: Incorrect Channel
INFO:discord.gateway:Shard ID None has successfully RESUMED session c69b02593bf94ed9f5653ae33812764b.
INFO:discord.gateway:Shard ID None has successfully RESUMED session c69b02593bf94ed9f5653ae33812764b.
INFO:discord.gateway:Shard ID None has successfully RESUMED session c69b02593bf94ed9f5653ae33812764b.
INFO:discord.gateway:Shard ID None has successfully RESUMED session c69b02593bf94ed9f5653ae33812764b.
INFO:discord.gateway:Shard ID None has successfully RESUMED session c69b02593bf94ed9f5653ae33812764b.
INFO:discord.gateway:Shard ID None has successfully RESUMED session c69b02593bf94ed9f5653ae33812764b.
INFO:discord.gateway:Shard ID None has successfully RESUMED session c69b02593bf94ed9f5653ae33812764b.
INFO:discord.gateway:Shard ID None has successfully RESUMED session c69b02593bf94ed9f5653ae33812764b.
INFO:discord.gateway:Shard ID None has successfully RESUMED session c69b02593bf94ed9f5653ae33812764b.
INFO:discord.gateway:Shard ID None has successfully RESUMED session c69b02593bf94ed9f5653ae33812764b.
INFO:discord.gateway:Shard ID None has successfully RESUMED session c69b02593bf94ed9f5653ae33812764b.
INFO:discord.gateway:Shard ID None has successfully RESUMED session c69b02593bf94ed9f5653ae33812764b.
INFO:discord.gateway:Shard ID None has successfully RESUMED session c69b02593bf94ed9f5653ae33812764b.
INFO:discord.gateway:Shard ID None has successfully RESUMED session c69b02593bf94ed9f5653ae33812764b.
INFO:discord.gateway:Shard ID None has successfully RESUMED session c69b02593bf94ed9f5653ae33812764b.
INFO:discord.gateway:Shard ID None has successfully RESUMED session c69b02593bf94ed9f5653ae33812764b.
INFO:discord.gateway:Shard ID None has successfully RESUMED session c69b02593bf94ed9f5653ae33812764b.
INFO:discord.gateway:Shard ID None has successfully RESUMED session c69b02593bf94ed9f5653ae33812764b.
INFO:discord.gateway:Shard ID None has successfully RESUMED session c69b02593bf94ed9f5653ae33812764b.
INFO:discord.gateway:Shard ID None has successfully RESUMED session c69b02593bf94ed9f5653ae33812764b.
INFO:discord.gateway:Shard ID None has successfully RESUMED session c69b02593bf94ed9f5653ae33812764b.
INFO:discord.gateway:Shard ID None has successfully RESUMED session c69b02593bf94ed9f5653ae33812764b.
INFO:discord.gateway:Shard ID None has successfully RESUMED session c69b02593bf94ed9f5653ae33812764b.
INFO:discord.gateway:Shard ID None has successfully RESUMED session c69b02593bf94ed9f5653ae33812764b.
INFO:discord.gateway:Shard ID None has successfully RESUMED session c69b02593bf94ed9f5653ae33812764b.
INFO:root:starting vanilla
INFO:root:Starting up browser
INFO:root:Visiting MCS portal
INFO:root:Logging In
INFO:root:Starting Vanilla in MCS portal
INFO:root:Browser has been Closed
INFO:root:Vanilla has been started at 09:07
INFO:root:starting vanilla
INFO:root:Starting up browser
INFO:root:Visiting MCS portal
INFO:root:Logging In
INFO:root:Starting Vanilla in MCS portal
INFO:root:Browser has been Closed
INFO:root:Vanilla has been started at 09:11
WARNING:discord.client:PyNaCl is not installed, voice will NOT be supported
INFO:root:2024-05-29 09:15:14  Starting Bot...
INFO:discord.client:logging in using static token
INFO:discord.gateway:Shard ID None has connected to Gateway (Session ID: 31dd73ded277f93551ae5998cb0e40d3).
INFO:__main__:Bot is Online and Ready!
INFO:root:stopping vanilla
INFO:root:Starting up browser
INFO:root:Visiting MCS portal
INFO:root:Logging In
INFO:root:Starting Vanilla in MCS portal
INFO:root:Browser has been Closed
INFO:root:Vanilla has been stopped at 09:15
INFO:root:starting vanilla
INFO:root:Starting up browser
INFO:root:Visiting MCS portal
INFO:root:Logging In
INFO:root:Starting Vanilla in MCS portal
INFO:root:Browser has been Closed
INFO:root:Vanilla has been started at 09:15
INFO:root:stopping vanilla
INFO:root:Starting up browser
INFO:root:Visiting MCS portal
INFO:root:Logging In
INFO:root:Starting Vanilla in MCS portal
INFO:root:Browser has been Closed
INFO:root:Vanilla has been stopped at 09:16
INFO:discord.gateway:Shard ID None has successfully RESUMED session 31dd73ded277f93551ae5998cb0e40d3.
INFO:discord.gateway:Shard ID None has successfully RESUMED session 31dd73ded277f93551ae5998cb0e40d3.
INFO:discord.gateway:Shard ID None has successfully RESUMED session 31dd73ded277f93551ae5998cb0e40d3.
INFO:discord.gateway:Shard ID None has successfully RESUMED session 31dd73ded277f93551ae5998cb0e40d3.
INFO:discord.gateway:Shard ID None has successfully RESUMED session 31dd73ded277f93551ae5998cb0e40d3.
